[WARNING] <2023-10-12 19:12:36,501> Add UpInfo {"name": "\u4ed8\u822a\u8131\u53e3\u79c0", "mid": 57592895, "sex": "\u4fdd\u5bc6", "sign": "\u770b\u6f14\u51fa\u5173\u6ce8\u516c\u4f17\u53f7\u5168\u7f51\u540c\u540d:\u4ed8\u822a\u8131\u53e3\u79c0 \n\u6f14\u51fa\u5ba2\u670d\u53ca\u5546\u52a1\u5408\u4f5c\u536b\u661f:fuhangtuokouxiu\n\u81ea\u7531\u4eba\u4e0d\u5c5e\u4e8e\u4efb\u4f55\u4ff1\u4e50\u90e8\u516c\u53f8   ", "level": 6, "title": "\u8131\u53e3\u79c0\u6f14\u5458", "face": "https://i2.hdslb.com/bfs/face/09f8e3e965220fe17cadf70893228f35d1d71e3f.jpg", "video": null, "follower": 1066863} Error for reason This Session's transaction has been rolled back due to a previous exception during flush. To begin a new transaction with this Session, first issue Session.rollback(). Original exception was: (pymysql.err.DataError) (1264, "Out of range value for column 'mid' at row 1")
[SQL: INSERT INTO up_infos (name, mid, sex, sign, level, title, face, video, follower, ext, created_at, updated_at) VALUES (%(name)s, %(mid)s, %(sex)s, %(sign)s, %(level)s, %(title)s, %(face)s, %(video)s, %(follower)s, %(ext)s, now(), now())]
[parameters: {'name': '蛋解杂谈', 'mid': 3493140174473954, 'sex': '保密', 'sign': '', 'level': 6, 'title': '', 'face': 'https://i2.hdslb.com/bfs/face/97125caa703e7f974fbd5412297c4356d3a723a8.jpg', 'video': None, 'follower': 93765, 'ext': None}]
(Background on this error at: https://sqlalche.me/e/20/9h9h) (Background on this error at: https://sqlalche.me/e/20/7s2a) (/Users/lyn/codes/python/BiliSpider/src/model/data/dataBili.py 55)
[WARNING] <2023-10-12 19:12:36,501> Add UpInfo {"name": "\u828b\u5706\u540c\u5b66\u5440", "mid": 373457457, "sex": "\u7537", "sign": "\u201c\u6b32\u901f\u5219\u4e0d\u8fbe\u201d\n\u7528\u5fc3\u5bf9\u5f85\u6bcf\u4e00\u90e8\u4f5c\u54c1", "level": 5, "title": "", "face": "https://i0.hdslb.com/bfs/face/9353ee2ebce0dbe92093d003dd8aa534e44805f6.jpg", "video": null, "follower": 1776} Error for reason This Session's transaction has been rolled back due to a previous exception during flush. To begin a new transaction with this Session, first issue Session.rollback(). Original exception was: (pymysql.err.DataError) (1264, "Out of range value for column 'mid' at row 1")
[SQL: INSERT INTO up_infos (name, mid, sex, sign, level, title, face, video, follower, ext, created_at, updated_at) VALUES (%(name)s, %(mid)s, %(sex)s, %(sign)s, %(level)s, %(title)s, %(face)s, %(video)s, %(follower)s, %(ext)s, now(), now())]
[parameters: {'name': '蛋解杂谈', 'mid': 3493140174473954, 'sex': '保密', 'sign': '', 'level': 6, 'title': '', 'face': 'https://i2.hdslb.com/bfs/face/97125caa703e7f974fbd5412297c4356d3a723a8.jpg', 'video': None, 'follower': 93765, 'ext': None}]
(Background on this error at: https://sqlalche.me/e/20/9h9h) (Background on this error at: https://sqlalche.me/e/20/7s2a) (/Users/lyn/codes/python/BiliSpider/src/model/data/dataBili.py 55)
[WARNING] <2023-10-12 19:12:36,501> Add UpInfo {"name": "\u585e\u62c9\u83f2\u5a1c_Serafina", "mid": 1025491703, "sex": "\u5973", "sign": "\u300c\u6781\u5149\u793e\u6240\u5c5e\u300d\u25c7\u80e1\u72fc\u534a\u795eVup\u25c7\u56db\u8bed\u6b4c\u52bf\u25c7\u76f4\u64ad\u6d3b\u52a8\u6682\u505c\u4e2d/\u975e\u6bd5\u4e1a\u25c7\u6cb9\u7ba1\uff1aSerafina Ch.", "level": 6, "title": "bilibili\u76f4\u64ad\u9ad8\u80fd\u4e3b\u64ad", "face": "https://i2.hdslb.com/bfs/face/0e3b8c78bec11570bdddef6bbd437a6e54b94288.jpg", "video": null, "follower": 356613} Error for reason This Session's transaction has been rolled back due to a previous exception during flush. To begin a new transaction with this Session, first issue Session.rollback(). Original exception was: (pymysql.err.DataError) (1264, "Out of range value for column 'mid' at row 1")
[SQL: INSERT INTO up_infos (name, mid, sex, sign, level, title, face, video, follower, ext, created_at, updated_at) VALUES (%(name)s, %(mid)s, %(sex)s, %(sign)s, %(level)s, %(title)s, %(face)s, %(video)s, %(follower)s, %(ext)s, now(), now())]
[parameters: {'name': '蛋解杂谈', 'mid': 3493140174473954, 'sex': '保密', 'sign': '', 'level': 6, 'title': '', 'face': 'https://i2.hdslb.com/bfs/face/97125caa703e7f974fbd5412297c4356d3a723a8.jpg', 'video': None, 'follower': 93765, 'ext': None}]
(Background on this error at: https://sqlalche.me/e/20/9h9h) (Background on this error at: https://sqlalche.me/e/20/7s2a) (/Users/lyn/codes/python/BiliSpider/src/model/data/dataBili.py 55)
[WARNING] <2023-10-12 19:12:36,502> Add UpInfo {"name": "\u5e26\u4f60\u73a9ai", "mid": 3493118949197945, "sex": "\u7537", "sign": "\u4e00\u952e\u4f53\u9a8cchatgpt-\u516c\u4f17\u53f7\uff1a\u8d1d\u591a\u52a9\u624b\u3002 \u4ea4\u6d41/\u5b66\u4e60/\u8f6f\u4ef6/\u5546\u52a1v\uff1adainichigua250", "level": 4, "title": "", "face": "https://i2.hdslb.com/bfs/face/6c034690e6ab4df6f09fe13d5d4a0119acbc9f43.jpg", "video": null, "follower": 19574} Error for reason This Session's transaction has been rolled back due to a previous exception during flush. To begin a new transaction with this Session, first issue Session.rollback(). Original exception was: (pymysql.err.DataError) (1264, "Out of range value for column 'mid' at row 1")
[SQL: INSERT INTO up_infos (name, mid, sex, sign, level, title, face, video, follower, ext, created_at, updated_at) VALUES (%(name)s, %(mid)s, %(sex)s, %(sign)s, %(level)s, %(title)s, %(face)s, %(video)s, %(follower)s, %(ext)s, now(), now())]
[parameters: {'name': '蛋解杂谈', 'mid': 3493140174473954, 'sex': '保密', 'sign': '', 'level': 6, 'title': '', 'face': 'https://i2.hdslb.com/bfs/face/97125caa703e7f974fbd5412297c4356d3a723a8.jpg', 'video': None, 'follower': 93765, 'ext': None}]
(Background on this error at: https://sqlalche.me/e/20/9h9h) (Background on this error at: https://sqlalche.me/e/20/7s2a) (/Users/lyn/codes/python/BiliSpider/src/model/data/dataBili.py 55)
[WARNING] <2023-10-12 19:12:36,502> Add UpInfo {"name": "\u8001\u738b\u65e5\u8bb0\u6cb9\u753b", "mid": 3546556351384136, "sex": "\u7537", "sign": "\u6cb9\u753b\u6362\u7269\n", "level": 2, "title": "", "face": "https://i2.hdslb.com/bfs/face/30bd786179f7d0fb3adc18b2ce47c84af4f4dec2.jpg", "video": null, "follower": 100134} Error for reason This Session's transaction has been rolled back due to a previous exception during flush. To begin a new transaction with this Session, first issue Session.rollback(). Original exception was: (pymysql.err.DataError) (1264, "Out of range value for column 'mid' at row 1")
[SQL: INSERT INTO up_infos (name, mid, sex, sign, level, title, face, video, follower, ext, created_at, updated_at) VALUES (%(name)s, %(mid)s, %(sex)s, %(sign)s, %(level)s, %(title)s, %(face)s, %(video)s, %(follower)s, %(ext)s, now(), now())]
[parameters: {'name': '蛋解杂谈', 'mid': 3493140174473954, 'sex': '保密', 'sign': '', 'level': 6, 'title': '', 'face': 'https://i2.hdslb.com/bfs/face/97125caa703e7f974fbd5412297c4356d3a723a8.jpg', 'video': None, 'follower': 93765, 'ext': None}]
(Background on this error at: https://sqlalche.me/e/20/9h9h) (Background on this error at: https://sqlalche.me/e/20/7s2a) (/Users/lyn/codes/python/BiliSpider/src/model/data/dataBili.py 55)
