[ERROR] <2023-10-07 18:31:27,397> Dao add instance failed for (pymysql.err.OperationalError) (1292, "Incorrect datetime value: 'now()' for column 'created_at' at row 1")
[SQL: INSERT INTO up_infos (name, mid, sex, sign, level, title, face, video, follower, ext, created_at, updated_at) VALUES (%(name)s, %(mid)s, %(sex)s, %(sign)s, %(level)s, %(title)s, %(face)s, %(video)s, %(follower)s, %(ext)s, %(created_at)s, %(updated_at)s)]
[parameters: {'name': 'Bili_12345', 'mid': 12345, 'sex': '男', 'sign': '', 'level': 3, 'title': '', 'face': 'https://i0.hdslb.com/bfs/face/5d2c92beb774a4bb30762538bb102d23670ae9c0.gif', 'video': 0, 'follower': 143, 'ext': None, 'created_at': <sqlalchemy.sql.functions.now at 0x110a1ab90; now>, 'updated_at': <sqlalchemy.sql.functions.now at 0x110a1aa70; now>}]
(Background on this error at: https://sqlalche.me/e/20/e3q8) (/Users/lyn/codes/python/BiliSpider/src/model/dao/__init__.py 24)
[ERROR] <2023-10-07 18:31:27,398> Dao addUpInfo failed (/Users/lyn/codes/python/BiliSpider/src/model/dao/upInfo.py 38)
[ERROR] <2023-10-12 14:57:26,916> Dao add instance failed for Class 'builtins.dict' is not mapped (/Users/lyn/codes/python/BiliSpider/src/model/dao/__init__.py 26)
[ERROR] <2023-10-12 14:57:27,786> Dao add instance failed for Class 'builtins.dict' is not mapped (/Users/lyn/codes/python/BiliSpider/src/model/dao/__init__.py 26)
[ERROR] <2023-10-12 14:57:28,695> Dao add instance failed for Class 'builtins.dict' is not mapped (/Users/lyn/codes/python/BiliSpider/src/model/dao/__init__.py 26)
[ERROR] <2023-10-12 14:57:29,405> Dao add instance failed for Class 'builtins.dict' is not mapped (/Users/lyn/codes/python/BiliSpider/src/model/dao/__init__.py 26)
[ERROR] <2023-10-12 14:57:30,383> Dao add instance failed for Class 'builtins.dict' is not mapped (/Users/lyn/codes/python/BiliSpider/src/model/dao/__init__.py 26)
[ERROR] <2023-10-12 14:58:44,636> Dao add instance failed for (pymysql.err.DataError) (1264, "Out of range value for column 'mid' at row 1")
[SQL: INSERT INTO up_infos (name, mid, sex, sign, level, title, face, video, follower, ext, created_at, updated_at) VALUES (%(name)s, %(mid)s, %(sex)s, %(sign)s, %(level)s, %(title)s, %(face)s, %(video)s, %(follower)s, %(ext)s, now(), now())]
[parameters: {'name': '带你玩ai', 'mid': 3493118949197945, 'sex': '男', 'sign': '一键体验chatgpt-公众号：贝多助手。 交流/学习/软件/商务v：dainichigua250', 'level': 4, 'title': '', 'face': 'https://i2.hdslb.com/bfs/face/6c034690e6ab4df6f09fe13d5d4a0119acbc9f43.jpg', 'video': 53, 'follower': 19277, 'ext': None}]
(Background on this error at: https://sqlalche.me/e/20/9h9h) (/Users/lyn/codes/python/BiliSpider/src/model/dao/__init__.py 26)
[ERROR] <2023-10-12 14:58:44,637> Dao addUpInfo failed (/Users/lyn/codes/python/BiliSpider/src/model/dao/daoUpInfo.py 38)
[ERROR] <2023-10-12 14:58:45,385> Dao add instance failed for This Session's transaction has been rolled back due to a previous exception during flush. To begin a new transaction with this Session, first issue Session.rollback(). Original exception was: (pymysql.err.DataError) (1264, "Out of range value for column 'mid' at row 1")
[SQL: INSERT INTO up_infos (name, mid, sex, sign, level, title, face, video, follower, ext, created_at, updated_at) VALUES (%(name)s, %(mid)s, %(sex)s, %(sign)s, %(level)s, %(title)s, %(face)s, %(video)s, %(follower)s, %(ext)s, now(), now())]
[parameters: {'name': '带你玩ai', 'mid': 3493118949197945, 'sex': '男', 'sign': '一键体验chatgpt-公众号：贝多助手。 交流/学习/软件/商务v：dainichigua250', 'level': 4, 'title': '', 'face': 'https://i2.hdslb.com/bfs/face/6c034690e6ab4df6f09fe13d5d4a0119acbc9f43.jpg', 'video': 53, 'follower': 19277, 'ext': None}]
(Background on this error at: https://sqlalche.me/e/20/9h9h) (Background on this error at: https://sqlalche.me/e/20/7s2a) (/Users/lyn/codes/python/BiliSpider/src/model/dao/__init__.py 26)
[ERROR] <2023-10-12 14:58:45,386> Dao addUpInfo failed (/Users/lyn/codes/python/BiliSpider/src/model/dao/daoUpInfo.py 38)
[ERROR] <2023-10-12 14:58:46,106> Dao add instance failed for This Session's transaction has been rolled back due to a previous exception during flush. To begin a new transaction with this Session, first issue Session.rollback(). Original exception was: (pymysql.err.DataError) (1264, "Out of range value for column 'mid' at row 1")
[SQL: INSERT INTO up_infos (name, mid, sex, sign, level, title, face, video, follower, ext, created_at, updated_at) VALUES (%(name)s, %(mid)s, %(sex)s, %(sign)s, %(level)s, %(title)s, %(face)s, %(video)s, %(follower)s, %(ext)s, now(), now())]
[parameters: {'name': '带你玩ai', 'mid': 3493118949197945, 'sex': '男', 'sign': '一键体验chatgpt-公众号：贝多助手。 交流/学习/软件/商务v：dainichigua250', 'level': 4, 'title': '', 'face': 'https://i2.hdslb.com/bfs/face/6c034690e6ab4df6f09fe13d5d4a0119acbc9f43.jpg', 'video': 53, 'follower': 19277, 'ext': None}]
(Background on this error at: https://sqlalche.me/e/20/9h9h) (Background on this error at: https://sqlalche.me/e/20/7s2a) (/Users/lyn/codes/python/BiliSpider/src/model/dao/__init__.py 26)
[ERROR] <2023-10-12 14:58:46,107> Dao addUpInfo failed (/Users/lyn/codes/python/BiliSpider/src/model/dao/daoUpInfo.py 38)
[ERROR] <2023-10-12 14:58:46,814> Dao add instance failed for This Session's transaction has been rolled back due to a previous exception during flush. To begin a new transaction with this Session, first issue Session.rollback(). Original exception was: (pymysql.err.DataError) (1264, "Out of range value for column 'mid' at row 1")
[SQL: INSERT INTO up_infos (name, mid, sex, sign, level, title, face, video, follower, ext, created_at, updated_at) VALUES (%(name)s, %(mid)s, %(sex)s, %(sign)s, %(level)s, %(title)s, %(face)s, %(video)s, %(follower)s, %(ext)s, now(), now())]
[parameters: {'name': '带你玩ai', 'mid': 3493118949197945, 'sex': '男', 'sign': '一键体验chatgpt-公众号：贝多助手。 交流/学习/软件/商务v：dainichigua250', 'level': 4, 'title': '', 'face': 'https://i2.hdslb.com/bfs/face/6c034690e6ab4df6f09fe13d5d4a0119acbc9f43.jpg', 'video': 53, 'follower': 19277, 'ext': None}]
(Background on this error at: https://sqlalche.me/e/20/9h9h) (Background on this error at: https://sqlalche.me/e/20/7s2a) (/Users/lyn/codes/python/BiliSpider/src/model/dao/__init__.py 26)
[ERROR] <2023-10-12 14:58:46,815> Dao addUpInfo failed (/Users/lyn/codes/python/BiliSpider/src/model/dao/daoUpInfo.py 38)
[ERROR] <2023-10-12 14:58:47,530> Dao add instance failed for This Session's transaction has been rolled back due to a previous exception during flush. To begin a new transaction with this Session, first issue Session.rollback(). Original exception was: (pymysql.err.DataError) (1264, "Out of range value for column 'mid' at row 1")
[SQL: INSERT INTO up_infos (name, mid, sex, sign, level, title, face, video, follower, ext, created_at, updated_at) VALUES (%(name)s, %(mid)s, %(sex)s, %(sign)s, %(level)s, %(title)s, %(face)s, %(video)s, %(follower)s, %(ext)s, now(), now())]
[parameters: {'name': '带你玩ai', 'mid': 3493118949197945, 'sex': '男', 'sign': '一键体验chatgpt-公众号：贝多助手。 交流/学习/软件/商务v：dainichigua250', 'level': 4, 'title': '', 'face': 'https://i2.hdslb.com/bfs/face/6c034690e6ab4df6f09fe13d5d4a0119acbc9f43.jpg', 'video': 53, 'follower': 19277, 'ext': None}]
(Background on this error at: https://sqlalche.me/e/20/9h9h) (Background on this error at: https://sqlalche.me/e/20/7s2a) (/Users/lyn/codes/python/BiliSpider/src/model/dao/__init__.py 26)
[ERROR] <2023-10-12 14:58:47,531> Dao addUpInfo failed (/Users/lyn/codes/python/BiliSpider/src/model/dao/daoUpInfo.py 38)
[ERROR] <2023-10-12 14:58:48,233> Dao add instance failed for This Session's transaction has been rolled back due to a previous exception during flush. To begin a new transaction with this Session, first issue Session.rollback(). Original exception was: (pymysql.err.DataError) (1264, "Out of range value for column 'mid' at row 1")
[SQL: INSERT INTO up_infos (name, mid, sex, sign, level, title, face, video, follower, ext, created_at, updated_at) VALUES (%(name)s, %(mid)s, %(sex)s, %(sign)s, %(level)s, %(title)s, %(face)s, %(video)s, %(follower)s, %(ext)s, now(), now())]
[parameters: {'name': '带你玩ai', 'mid': 3493118949197945, 'sex': '男', 'sign': '一键体验chatgpt-公众号：贝多助手。 交流/学习/软件/商务v：dainichigua250', 'level': 4, 'title': '', 'face': 'https://i2.hdslb.com/bfs/face/6c034690e6ab4df6f09fe13d5d4a0119acbc9f43.jpg', 'video': 53, 'follower': 19277, 'ext': None}]
(Background on this error at: https://sqlalche.me/e/20/9h9h) (Background on this error at: https://sqlalche.me/e/20/7s2a) (/Users/lyn/codes/python/BiliSpider/src/model/dao/__init__.py 26)
[ERROR] <2023-10-12 14:58:48,234> Dao addUpInfo failed (/Users/lyn/codes/python/BiliSpider/src/model/dao/daoUpInfo.py 38)
[ERROR] <2023-10-12 19:08:23,914> Dao add instance failed for (pymysql.err.DataError) (1264, "Out of range value for column 'mid' at row 1")
[SQL: INSERT INTO up_infos (name, mid, sex, sign, level, title, face, video, follower, ext, created_at, updated_at) VALUES (%(name)s, %(mid)s, %(sex)s, %(sign)s, %(level)s, %(title)s, %(face)s, %(video)s, %(follower)s, %(ext)s, now(), now())]
[parameters: {'name': '老王日记油画', 'mid': 3546556351384136, 'sex': '男', 'sign': '油画换物\n', 'level': 2, 'title': '', 'face': 'https://i2.hdslb.com/bfs/face/30bd786179f7d0fb3adc18b2ce47c84af4f4dec2.jpg', 'video': None, 'follower': 99993, 'ext': None}]
(Background on this error at: https://sqlalche.me/e/20/9h9h) (/Users/lyn/codes/python/BiliSpider/src/model/dao/__init__.py 26)
[ERROR] <2023-10-12 19:08:23,915> Dao addUpInfo failed (/Users/lyn/codes/python/BiliSpider/src/model/dao/daoUpInfo.py 38)
[ERROR] <2023-10-12 19:12:36,500> Dao add instance failed for (pymysql.err.DataError) (1264, "Out of range value for column 'mid' at row 1")
[SQL: INSERT INTO up_infos (name, mid, sex, sign, level, title, face, video, follower, ext, created_at, updated_at) VALUES (%(name)s, %(mid)s, %(sex)s, %(sign)s, %(level)s, %(title)s, %(face)s, %(video)s, %(follower)s, %(ext)s, now(), now())]
[parameters: {'name': '蛋解杂谈', 'mid': 3493140174473954, 'sex': '保密', 'sign': '', 'level': 6, 'title': '', 'face': 'https://i2.hdslb.com/bfs/face/97125caa703e7f974fbd5412297c4356d3a723a8.jpg', 'video': None, 'follower': 93765, 'ext': None}]
(Background on this error at: https://sqlalche.me/e/20/9h9h) (/Users/lyn/codes/python/BiliSpider/src/model/dao/__init__.py 26)
[ERROR] <2023-10-12 19:12:36,500> Dao addUpInfo failed (/Users/lyn/codes/python/BiliSpider/src/model/dao/daoUpInfo.py 38)
[ERROR] <2023-10-13 20:57:27,521> Transform to VideoInfo failed for reason model.dao.daoVideoInfo.VideoInfo() argument after ** must be a mapping, not DaoVideoInfo (/Users/lyn/codes/python/BiliSpider/model/dao/daoVideoInfo.py 48)
[ERROR] <2023-10-13 20:58:03,032> Transform to VideoInfo failed for reason 'title' is an invalid keyword argument for VideoInfo (/Users/lyn/codes/python/BiliSpider/model/dao/daoVideoInfo.py 48)
[ERROR] <2023-10-13 20:58:59,629> Dao add instance failed for (pymysql.err.OperationalError) (1054, "Unknown column 'title' in 'field list'")
[SQL: INSERT INTO video_infos (aid, bvid, tid, tname, pic, title, pubdate, `desc`, duration, upname, mid, `like`, coin, favorite, share, view, danmaku, reply, his_rank, created_at, updated_at) VALUES (%(aid)s, %(bvid)s, %(tid)s, %(tname)s, %(pic)s, %(title)s, %(pubdate)s, %(desc)s, %(duration)s, %(upname)s, %(mid)s, %(like)s, %(coin)s, %(favorite)s, %(share)s, %(view)s, %(danmaku)s, %(reply)s, %(his_rank)s, now(), now())]
[parameters: {'aid': 746931433, 'bvid': 'BV16C4y1V7XY', 'tid': 182, 'tname': '影视杂谈', 'pic': 'http://i0.hdslb.com/bfs/archive/031e2d3f1e5ec010f8a9153019da8e8348628503.jpg', 'title': '以暴制暴！众生皆苦，唯有自渡。群像剧中看到了真大女主！《那些回不去的年少时光》', 'pubdate': 1696649588, 'desc': '激励一代人的硬核大女主成长史诗', 'duration': 982, 'upname': 'low君热剧', 'mid': 34189415, 'like': 38054, 'coin': 7789, 'favorite': 7679, 'share': 3173, 'view': 913328, 'danmaku': 2451, 'reply': 1607, 'his_rank': 0}]
(Background on this error at: https://sqlalche.me/e/20/e3q8) (/Users/lyn/codes/python/BiliSpider/model/dao/__init__.py 26)
[WARNING] <2023-10-13 20:58:59,629> Insert video info fail! (/Users/lyn/codes/python/BiliSpider/model/dao/daoVideoInfo.py 53)
